<?xml version="1.0" encoding="utf-8"?>
<!-- This URDF was automatically created by SolidWorks to URDF Exporter! Originally created by Stephen Brawner (brawner@gmail.com) 
     Commit Version: 1.6.0-4-g7f85cfe  Build Version: 1.6.7995.38578
     For more information, please see http://wiki.ros.org/sw_urdf_exporter -->
<robot
  name="robot_arm_urdf.SLDASM">
  <link
    name="base_link">
    <inertial>
      <origin
        xyz="1.8041E-16 -6.6678E-18 0.073876"
        rpy="0 0 0" />
      <mass
        value="17.147" />
      <inertia
        ixx="0.192"
        ixy="-4.9423E-10"
        ixz="4.9848E-17"
        iyy="0.192"
        iyz="-3.3494E-18"
        izz="0.29544" />
    </inertial>
    <visual>
      <origin
        xyz="0 0 0"
        rpy="0 0 0" />
      <geometry>
        <mesh
          filename="package://robot_arm_urdf.SLDASM/meshes/base_link.STL" />
      </geometry>
      <material
        name="">
        <color
          rgba="0.79216 0.81961 0.93333 1" />
      </material>
    </visual>
    <collision>
      <origin
        xyz="0 0 0"
        rpy="0 0 0" />
      <geometry>
        <mesh
          filename="package://robot_arm_urdf.SLDASM/meshes/base_link.STL" />
      </geometry>
    </collision>
  </link>
  <link
    name="link_1">
    <inertial>
      <origin
        xyz="-2.5729E-14 0.11047 -7.8988E-11"
        rpy="0 0 0" />
      <mass
        value="3.0905" />
      <inertia
        ixx="0.026302"
        ixy="-2.5304E-15"
        ixz="-1.4177E-12"
        iyy="0.019632"
        iyz="-7.4535E-12"
        izz="0.025388" />
    </inertial>
    <visual>
      <origin
        xyz="0 0 0"
        rpy="0 0 0" />
      <geometry>
        <mesh
          filename="package://robot_arm_urdf.SLDASM/meshes/link_1.STL" />
      </geometry>
      <material
        name="">
        <color
          rgba="1 1 1 1" />
      </material>
    </visual>
    <collision>
      <origin
        xyz="0 0 0"
        rpy="0 0 0" />
      <geometry>
        <mesh
          filename="package://robot_arm_urdf.SLDASM/meshes/link_1.STL" />
      </geometry>
    </collision>
  </link>
  <joint
    name="joint_1"
    type="revolute">
    <origin
      xyz="0 0 0.2"
      rpy="1.5708 0 0" />
    <parent
      link="base_link" />
    <child
      link="link_1" />
    <axis
      xyz="0 1 0" />
    <limit
      lower="0"
      upper="3.142"
      effort="300"
      velocity="3" />
  </joint>
  <link
    name="link_2">
    <inertial>
      <origin
        xyz="0 0.16752 2.949E-17"
        rpy="0 0 0" />
      <mass
        value="5.5867" />
      <inertia
        ixx="0.12632"
        ixy="1.5322E-18"
        ixz="1.6666E-19"
        iyy="0.011401"
        iyz="4.7218E-18"
        izz="0.12911" />
    </inertial>
    <visual>
      <origin
        xyz="0 0 0"
        rpy="0 0 0" />
      <geometry>
        <mesh
          filename="package://robot_arm_urdf.SLDASM/meshes/link_2.STL" />
      </geometry>
      <material
        name="">
        <color
          rgba="0.79216 0.81961 0.93333 1" />
      </material>
    </visual>
    <collision>
      <origin
        xyz="0 0 0"
        rpy="0 0 0" />
      <geometry>
        <mesh
          filename="package://robot_arm_urdf.SLDASM/meshes/link_2.STL" />
      </geometry>
    </collision>
  </link>
  <joint
    name="joint_2"
    type="revolute">
    <origin
      xyz="0 0.205 0"
      rpy="0 0 0" />
    <parent
      link="link_1" />
    <child
      link="link_2" />
    <axis
      xyz="0 0 1" />
    <limit
      lower="-1.57"
      upper="1.57"
      effort="200"
      velocity="3" />
  </joint>
  <link
    name="link_3">
    <inertial>
      <origin
        xyz="-0.17893 1.1102E-16 -1.5179E-18"
        rpy="0 0 0" />
      <mass
        value="2.8262" />
      <inertia
        ixx="0.0074041"
        ixy="-8.3207E-18"
        ixz="4.0036E-17"
        iyy="0.028552"
        iyz="-3.4736E-10"
        izz="0.025128" />
    </inertial>
    <visual>
      <origin
        xyz="0 0 0"
        rpy="0 0 0" />
      <geometry>
        <mesh
          filename="package://robot_arm_urdf.SLDASM/meshes/link_3.STL" />
      </geometry>
      <material
        name="">
        <color
          rgba="0.79216 0.81961 0.93333 1" />
      </material>
    </visual>
    <collision>
      <origin
        xyz="0 0 0"
        rpy="0 0 0" />
      <geometry>
        <mesh
          filename="package://robot_arm_urdf.SLDASM/meshes/link_3.STL" />
      </geometry>
    </collision>
  </link>
  <joint
    name="joint_3"
    type="revolute">
    <origin
      xyz="0 0.4 0"
      rpy="0 0 0" />
    <parent
      link="link_2" />
    <child
      link="link_3" />
    <axis
      xyz="0 0 1" />
    <limit
      lower="0"
      upper="3.142"
      effort="200"
      velocity="3" />
  </joint>
  <link
    name="link_4">
    <inertial>
      <origin
        xyz="-0.051672 -5.5511E-17 5.4752E-18"
        rpy="0 0 0" />
      <mass
        value="1.8097" />
      <inertia
        ixx="0.0023112"
        ixy="-6.13E-18"
        ixz="2.5903E-19"
        iyy="0.0096102"
        iyz="-1.1374E-19"
        izz="0.0093908" />
    </inertial>
    <visual>
      <origin
        xyz="0 0 0"
        rpy="0 0 0" />
      <geometry>
        <mesh
          filename="package://robot_arm_urdf.SLDASM/meshes/link_4.STL" />
      </geometry>
      <material
        name="">
        <color
          rgba="0.79216 0.81961 0.93333 1" />
      </material>
    </visual>
    <collision>
      <origin
        xyz="0 0 0"
        rpy="0 0 0" />
      <geometry>
        <mesh
          filename="package://robot_arm_urdf.SLDASM/meshes/link_4.STL" />
      </geometry>
    </collision>
  </link>
  <joint
    name="joint_4"
    type="revolute">
    <origin
      xyz="-0.35 0 0"
      rpy="0 0 1.5708" />
    <parent
      link="link_3" />
    <child
      link="link_4" />
    <axis
      xyz="0 0 1" />
    <limit
      lower="0"
      upper="-3.142"
      effort="200"
      velocity="3" />
  </joint>
  <link
    name="link_5">
    <inertial>
      <origin
        xyz="-0.018544 0 3.1659E-17"
        rpy="0 0 0" />
      <mass
        value="0.19053" />
      <inertia
        ixx="0.00030197"
        ixy="-5.4657E-20"
        ixz="3.6426E-21"
        iyy="0.00022817"
        iyz="-1.9664E-11"
        izz="0.00011843" />
    </inertial>
    <visual>
      <origin
        xyz="0 0 0"
        rpy="0 0 0" />
      <geometry>
        <mesh
          filename="package://robot_arm_urdf.SLDASM/meshes/link_5.STL" />
      </geometry>
      <material
        name="">
        <color
          rgba="0.79216 0.81961 0.93333 1" />
      </material>
    </visual>
    <collision>
      <origin
        xyz="0 0 0"
        rpy="0 0 0" />
      <geometry>
        <mesh
          filename="package://robot_arm_urdf.SLDASM/meshes/link_5.STL" />
      </geometry>
    </collision>
  </link>
  <joint
    name="joint_5"
    type="revolute">
    <origin
      xyz="-0.188 0 0"
      rpy="0 0 0" />
    <parent
      link="link_4" />
    <child
      link="link_5" />
    <axis
      xyz="-1 0 0" />
    <limit
      lower="0"
      upper="3.142"
      effort="200"
      velocity="3" />
  </joint>
  <link
    name="link_6">
    <inertial>
      <origin
        xyz="-0.60237 0.4 -0.016013"
        rpy="0 0 0" />
      <mass
        value="0.11653" />
      <inertia
        ixx="3.9246E-05"
        ixy="6.5415E-20"
        ixz="1.0258E-05"
        iyy="7.1189E-05"
        iyz="-5.274E-20"
        izz="8.4875E-05" />
    </inertial>
    <visual>
      <origin
        xyz="0 0 0"
        rpy="0 0 0" />
      <geometry>
        <mesh
          filename="package://robot_arm_urdf.SLDASM/meshes/link_6.STL" />
      </geometry>
      <material
        name="">
        <color
          rgba="0.79216 0.81961 0.93333 1" />
      </material>
    </visual>
    <collision>
      <origin
        xyz="0 0 0"
        rpy="0 0 0" />
      <geometry>
        <mesh
          filename="package://robot_arm_urdf.SLDASM/meshes/link_6.STL" />
      </geometry>
    </collision>
  </link>
  <joint
    name="joint_6"
    type="prismatic">
    <origin
      xyz="0.54 0.4 0"
      rpy="3.1416 0 0" />
    <parent
      link="link_5" />
    <child
      link="link_6" />
    <axis
      xyz="0 0 1" />
    <limit
      lower="-0.03"
      upper="0"
      effort="100"
      velocity="3" />
  </joint>
  <link
    name="link_7">
    <inertial>
      <origin
        xyz="-0.60237 0.4 -0.016013"
        rpy="0 0 0" />
      <mass
        value="0.11653" />
      <inertia
        ixx="3.9246E-05"
        ixy="3.4641E-20"
        ixz="1.0258E-05"
        iyy="7.1189E-05"
        iyz="-2.7813E-20"
        izz="8.4875E-05" />
    </inertial>
    <visual>
      <origin
        xyz="0 0 0"
        rpy="0 0 0" />
      <geometry>
        <mesh
          filename="package://robot_arm_urdf.SLDASM/meshes/link_7.STL" />
      </geometry>
      <material
        name="">
        <color
          rgba="0.79216 0.81961 0.93333 1" />
      </material>
    </visual>
    <collision>
      <origin
        xyz="0 0 0"
        rpy="0 0 0" />
      <geometry>
        <mesh
          filename="package://robot_arm_urdf.SLDASM/meshes/link_7.STL" />
      </geometry>
    </collision>
  </link>
  <joint
    name="joint_7"
    type="prismatic">
    <origin
      xyz="0.54 -0.4 0"
      rpy="0 0 0" />
    <parent
      link="link_5" />
    <child
      link="link_7" />
    <axis
      xyz="0 0 -1" />
    <limit
      lower="0"
      upper="0.03"
      effort="100"
      velocity="3" />
  </joint>
</robot>